Workbook
Name Slicer_Income_sources: #N/A
Name Slicer_Year: #N/A

Sheet Synthetic Data
A1: Year | B1: Month | C1: Income sources | D1: Income Breakdowns | E1: Counts | F1: Income | G1: Target Income | H1: Operating profit | I1: Marketing Strategies | J1: date | L1: Year | M1: Country | N1: Amount | O1: Target | P1: Stage
A2: 2020 | B2: Jan | C2: Asset sale | D2: New | E2: 2051 | F2: 9126 | G2: 11327 | H2: 427 | I2: Mixed | J2: =DATE(Table2[[#This Row],[Year]],MONTH(1 & Table2[[#This Row],[Month]]),RANDBETWEEN(1,30)) -> 43842 | L2: 2022 | M2: Canada | N2: 132246 | O2: 352245 | P2: Current Stage
A3: 2020 | B3: Jan | C3: Usage fees | D3: Facebook Page | E3: 3780 | F3: 2836 | G3: 4595 | H3: 856 | I3: B2B | J3: =DATE(Table2[[#This Row],[Year]],MONTH(1 & Table2[[#This Row],[Month]]),RANDBETWEEN(1,30)) -> 43847 | L3: 2025 | M3: Canada | N3: 475827 | O3: 691473 | P3: Total Project
A4: 2020 | B4: Jan | C4: Advertising | D4: Company Website | E4: 2368 | F4: 3659 | G4: 8465 | H4: 1759 | I4: Mixed | J4: =DATE(Table2[[#This Row],[Year]],MONTH(1 & Table2[[#This Row],[Month]]),RANDBETWEEN(1,30)) -> 43845 | L4: 2020 | M4: Egypt | N4: 402053 | O4: 521389 | P4: Total Project
A5: 2020 | B5: Jan | C5: Usage fees | D5: Company Website | E5: 2984 | F5: 5280 | G5: 3909 | H5: 2478 | I5: B2B | J5: =DATE(Table2[[#This Row],[Year]],MONTH(1 & Table2[[#This Row],[Month]]),RANDBETWEEN(1,30)) -> 43837 | L5: 2022 | M5: Australia | N5: 334650 | O5: 558838 | P5: Total Project
A6: 2020 | B6: Jan | C6: Subscription | D6: Equipments | E6: 2409 | F6: 5567 | G6: 3604 | H6: 1779 | I6: B2C | J6: =DATE(Table2[[#This Row],[Year]],MONTH(1 & Table2[[#This Row],[Month]]),RANDBETWEEN(1,30)) -> 43850 | L6: 2022 | M6: Egypt | N6: 431375 | O6: 688309 | P6: Saving
A7: 2020 | B7: Jan | C7: Usage fees | D7: Software Metered License | E7: 3269 | F7: 9012 | G7: 4763 | H7: 1730 | I7: Mixed | J7: =DATE(Table2[[#This Row],[Year]],MONTH(1 & Table2[[#This Row],[Month]]),RANDBETWEEN(1,30)) -> 43831 | L7: 2022 | M7: USA | N7: 132075 | O7: 388601 | P7: Saving
A8: 2020 | B8: Jan | C8: Asset sale | D8: Company Website | E8: 876 | F8: 2863 | G8: 11528 | H8: 1540 | I8: B2B | J8: =DATE(Table2[[#This Row],[Year]],MONTH(1 & Table2[[#This Row],[Month]]),RANDBETWEEN(1,30)) -> 43835 | L8: 2021 | M8: Russia | N8: 290736 | O8: 600920 | P8: Total Project
A9: 2020 | B9: Jan | C9: Usage fees | D9: New | E9: 3470 | F9: 7637 | G9: 7951 | H9: 691 | I9: B2C | J9: =DATE(Table2[[#This Row],[Year]],MONTH(1 & Table2[[#This Row],[Month]]),RANDBETWEEN(1,30)) -> 43843 | L9: 2021 | M9: United Kingdom | N9: 352037 | O9: 417265 | P9: Total Project
A10: 2020 | B10: Jan | C10: Advertising | D10: Youtube Channel | E10: 1809 | F10: 5484 | G10: 9610 | H10: 2311 | I10: Mixed | J10: =DATE(Table2[[#This Row],[Year]],MONTH(1 & Table2[[#This Row],[Month]]),RANDBETWEEN(1,30)) -> 43838 | L10: 2022 | M10: Brazil | N10: 431461 | O10: 634767 | P10: Current Stage
A11: 2020 | B11: Jan | C11: Asset sale | D11: Asset sale | E11: 2405 | F11: 5252 | G11: 5098 | H11: 1951 | I11: Mixed | J11: =DATE(Table2[[#This Row],[Year]],MONTH(1 & Table2[[#This Row],[Month]]),RANDBETWEEN(1,30)) -> 43839 | L11: 2020 | M11: France | N11: 413388 | O11: 290329 | P11: Finance
A12: 2020 | B12: Feb | C12: Asset sale | D12: Asset sale | E12: 763 | F12: 6727 | G12: 11812 | H12: 2364 | I12: Mixed | J12: =DATE(Table2[[#This Row],[Year]],MONTH(1 & Table2[[#This Row],[Month]]),RANDBETWEEN(1,30)) -> 43869 | L12: 2020 | M12: Canada | N12: 210828 | O12: 673843 | P12: Total Project
A13: 2020 | B13: Feb | C13: Asset sale | D13: New | E13: 2148 | F13: 3028 | G13: 11522 | H13: 2814 | I13: B2C | J13: =DATE(Table2[[#This Row],[Year]],MONTH(1 & Table2[[#This Row],[Month]]),RANDBETWEEN(1,30)) -> 43878 | L13: 2023 | M13: Canada | N13: 476352 | O13: 309386 | P13: Finance
... A901: 2025 | B901: Dec | C901: Asset sale | D901: New | E901: 3913 | F901: 9812 | G901: 4674 | H901: 2405 | I901: B2C | J901: =DATE(Table2[[#This Row],[Year]],MONTH(1 & Table2[[#This Row],[Month]]),RANDBETWEEN(1,30)) -> 46004 | L901: 2020 | M901: Germany | N901: 213106 | O901: 637199 | P901: Total Project

Sheet pivots
A1: Row Labels | B1: Sum of Income | C1: income% | D1: Sum of Counts | E1: Sum of Counts2
A2: Advertising | B2: 155043 | C2: 0.18646069 | D2: 41322 | E2: 0.15978377
A3: Asset sale | B3: 123638 | C3: 0.14869183 | D3: 37287 | E3: 0.14418124 | H3: X | I3: Y | J3: AMOUNT | K3: MAX | L3: without max | M3: Count | N3: Count% | O3: income%
A4: Licensing | B4: 141331 | C4: 0.16997011 | D4: 48824 | E4: 0.18879248 | G4: Advertising | H4: 1 | I4: 3 | J4: =B2 -> 155043 | K4: =IF($J4=MAX($J$4:$J$9),$J4,"") | L4: =IF($J4=MAX($J$4:$J$9),"",$J4) -> 155043 | M4: =VLOOKUP($G4,$A$1:$E$7,4,0) -> 41322 | N4: =VLOOKUP($G4,$A$1:$E$7,5,0) -> 0.15978377 | O4: =VLOOKUP($G4,$A$1:$E$7,3,0) -> 0.18646069 | P4: Sum of Income | Q4: Sum of Target Income | S4: income | T4: Target | V4: Row Labels | W4: Sum of Income | X4: Sum of Income2 | Z4: Avg. income per month | AB4: Row Labels | AC4: Sum of Operating profit | AE4: Operating Profits | AG4: Row Labels | AH4: Sum of Income | AI4: profit%
A5: Renting | B5: 155344 | C5: 0.18682269 | D5: 43393 | E5: 0.1677919 | G5: Asset sale | H5: 7 | I5: 2 | J5: =B3 -> 123638 | K5: =IF($J5=MAX($J$4:$J$9),$J5,"") | L5: =IF($J5=MAX($J$4:$J$9),"",$J5) -> 123638 | M5: =VLOOKUP($G5,$A$1:$E$7,4,0) -> 37287 | N5: =VLOOKUP($G5,$A$1:$E$7,5,0) -> 0.14418124 | O5: =VLOOKUP($G5,$A$1:$E$7,3,0) -> 0.14869183 | P5: 831505 | Q5: 1014464 | S5: =$P$5/$Q$5 -> 0.81964959 | T5: =1-S5 -> 0.18035041 | V5: Jan | W5: 68039 | X5: 68039 | Z5: =AVERAGE($W$5:$W$16) -> 69292.083 | AB5: Jan | AC5: 13117 | AE5: =AC17 -> 229111 | AG5: B2B | AH5: 262044 | AI5: 0.45823745 | AK5: B2B | AL5: =AH5 -> 262044 | AM5: =AI5 -> 0.45823745
A6: Subscription | B6: 132528 | C6: 0.15938329 | D6: 40532 | E6: 0.156729 | G6: Licensing | H6: 4 | I6: 1 | J6: =B4 -> 141331 | K6: =IF($J6=MAX($J$4:$J$9),$J6,"") | L6: =IF($J6=MAX($J$4:$J$9),"",$J6) -> 141331 | M6: =VLOOKUP($G6,$A$1:$E$7,4,0) -> 48824 | N6: =VLOOKUP($G6,$A$1:$E$7,5,0) -> 0.18879248 | O6: =VLOOKUP($G6,$A$1:$E$7,3,0) -> 0.16997011 | V6: Feb | W6: 103772 | X6: 103772 | AB6: Feb | AC6: 24899 | AG6: B2C | AH6: 309808 | AI6: 0.54176255 | AK6: B2C | AL6: =AH6 -> 309808 | AM6: =AI6 -> 0.54176255
A7: Usage fees | B7: 123621 | C7: 0.14867139 | D7: 47254 | E7: 0.18272161 | G7: Renting | H7: 2 | I7: 8 | J7: =B5 -> 155344 | K7: =IF($J7=MAX($J$4:$J$9),$J7,"") -> 155344 | L7: =IF($J7=MAX($J$4:$J$9),"",$J7) | M7: =VLOOKUP($G7,$A$1:$E$7,4,0) -> 43393 | N7: =VLOOKUP($G7,$A$1:$E$7,5,0) -> 0.1677919 | O7: =VLOOKUP($G7,$A$1:$E$7,3,0) -> 0.18682269 | V7: Mar | W7: 70105 | X7: 70105 | AB7: Mar | AC7: 15810 | AG7: Grand Total | AH7: 571852 | AI7: 1
G8: Subscription | H8: 6 | I8: 6 | J8: =B6 -> 132528 | K8: =IF($J8=MAX($J$4:$J$9),$J8,"") | L8: =IF($J8=MAX($J$4:$J$9),"",$J8) -> 132528 | M8: =VLOOKUP($G8,$A$1:$E$7,4,0) -> 40532 | N8: =VLOOKUP($G8,$A$1:$E$7,5,0) -> 0.156729 | O8: =VLOOKUP($G8,$A$1:$E$7,3,0) -> 0.15938329 | V8: Apr | W8: 84134 | X8: 84134 | AB8: Apr | AC8: 22147
G9: Usage fees | H9: 5 | I9: 9 | J9: =B7 -> 123621 | K9: =IF($J9=MAX($J$4:$J$9),$J9,"") | L9: =IF($J9=MAX($J$4:$J$9),"",$J9) -> 123621 | M9: =VLOOKUP($G9,$A$1:$E$7,4,0) -> 47254 | N9: =VLOOKUP($G9,$A$1:$E$7,5,0) -> 0.18272161 | O9: =VLOOKUP($G9,$A$1:$E$7,3,0) -> 0.14867139 | V9: May | W9: 49511 | X9: 49511 | AB9: May | AC9: 14925
O10: =SUM(O4:O9) -> 1 | V10: Jun | W10: 32165 | X10: 32165 | AB10: Jun | AC10: 13824
V11: Jul | W11: 62268 | X11: 62268 | AB11: Jul | AC11: 18742 | AG11: Row Labels | AH11: Sum of Income | AI11: profit%
A12: Advertising | V12: Aug | W12: 66842 | X12: 66842 | AB12: Aug | AC12: 23466 | AG12: Advertising
A13: Asset sale | V13: Sep | W13: 90725 | X13: 90725 | AB13: Sep | AC13: 19194 | AG13: Asset sale | AH13: 3635 | AI13: 0.0043715913
A14: Licensing | V14: Oct | W14: 110420 | X14: 110420 | AB14: Oct | AC14: 26230 | AG14: Company Website | AH14: 9305 | AI14: 0.011190552
A15: Renting | V15: Nov | W15: 28892 | X15: 28892 | AB15: Nov | AC15: 7952 | AG15: Facebook Page | AH15: 12387 | AI15: 0.014897084
A16: Subscription | V16: Dec | W16: 64632 | X16: 64632 | AB16: Dec | AC16: 28805 | AG16: Floating License | AH16: 21410 | AI16: 0.025748492
A17: Usage fees | AB17: Grand Total | AC17: 229111 | AG17: Google Ad | AH17: 17673 | AI17: 0.021254232
AG18: Lands | AH18: 19528 | AI18: 0.023485126
T19: vio;rt | AG19: New | AH19: 11840 | AI19: 0.014239241
T20: 1 | AG20: Offices | AH20: 16896 | AI20: 0.020319782
T21: 1 | AG21: Premium | AH21: 9511 | AI21: 0.011438296
T22: 1 | AG22: Prime | AH22: 1248 | AI22: 0.001500893
T23: 1 | AG23: Renewal | AH23: 17210 | AI23: 0.02069741
T24: 1 | AG24: Software Metered License | AH24: 7990 | AI24: 0.0096090823
T25: 1 | AG25: Youtube Channel | AH25: 6410 | AI25: 0.0077089134
T26: 1 | AG26: Asset sale
T27: 1 | AG27: Company Website | AH27: 7017 | AI27: 0.008438915
T28: 1 | AG28: Equipments | AH28: 4769 | AI28: 0.0057353834
T29: 1 | AG29: Facebook Page | AH29: 14796 | AI29: 0.017794241
T30: 1 | AG30: Lands | AH30: 9717 | AI30: 0.011686039
T31: 1 | AG31: Offices | AH31: 4371 | AI31: 0.0052567333
T32: 1 | AG32: Premium | AH32: 20880 | AI32: 0.025111094
T33: 1 | AG33: Prime | AH33: 8064 | AI33: 0.0096980776
T34: 1 | AG34: Renewal | AH34: 20010 | AI34: 0.024064798
T35: 1 | AG35: Software Metered License | AH35: 23372 | AI35: 0.028108069
T36: 1 | AG36: Youtube Channel | AH36: 10642 | AI36: 0.01279848
T37: 1 | AG37: Licensing
T38: 1 | AG38: Asset sale | AH38: 3022 | AI38: 0.0036343738
T39: 1 | AG39: Company Website | AH39: 9955 | AI39: 0.011972267
T40: 1 | AG40: Equipments | AH40: 33963 | AI40: 0.040845214
...

Sheet Income sources
T4: MoM%
T6: =pivots!N135 -> 0.077447192
T7: =T6 -> 0.077447192
A9: g
T12: =pivots!N136 -> 0.063419387
T13: =T12 -> 0.063419387
T18: =pivots!N137 -> 0.063419387
T19: =T18 -> 0.063419387
A24: v
T25: =pivots!N138 -> 0.077151277
T26: =T25 -> 0.077151277
T31: =pivots!N139 -> 0.09094415
T32: =T31 -> 0.09094415
